Workbook

Sheet 05_Dashboard
A1: PHOTO LAB — Master Timeline v0.20
A2: KPI | B2: Значение | C2: Комментарий
A3: Всего исторических узлов | B3: =COUNTA('01_Master_Facts'!$A$2:$A$800) | C3: Количество строк в 01_Master_Facts
A4: Узлов с важностью 5 | B4: =COUNTIF('01_Master_Facts'!$N$2:$N$800,5) | C4: Критические для карты и уроков
A5: Узлов для PL-001–PL-041 | B5: =SUM(E10:E55) | C5: Узлы для заполненных PL; PL-040 пока планируется и даёт 0 узлов
A6: Строк с пометкой «проверить позже» | B6: =COUNTA('01_Master_Facts'!$W$2:$W$800) | C6: Живая формула: считает непустые ячейки в «Проверить позже»
A9: Ветка развития | B9: Количество узлов | D9: Урок | E9: Количество узлов
A10: Оптика / камера-обскура | B10: =COUNTIF('01_Master_Facts'!$H$2:$H$800,A10) | D10: PL-001 | E10: =COUNTIF('01_Master_Facts'!$O$2:$O$800,D10)
A11: Оптические инструменты | B11: =COUNTIF('01_Master_Facts'!$H$2:$H$800,A11) | D11: PL-002 | E11: =COUNTIF('01_Master_Facts'!$O$2:$O$800,D11)
A12: Фотохимия | B12: =COUNTIF('01_Master_Facts'!$H$2:$H$800,A12) | D12: PL-003 | E12: =COUNTIF('01_Master_Facts'!$O$2:$O$800,D12)
A13: Гелиография | B13: =COUNTIF('01_Master_Facts'!$H$2:$H$800,A13) | D13: PL-004 | E13: =COUNTIF('01_Master_Facts'!$O$2:$O$800,D13)
A14: Дагеротип | B14: =COUNTIF('01_Master_Facts'!$H$2:$H$800,A14) | D14: PL-005 | E14: =COUNTIF('01_Master_Facts'!$O$2:$O$800,D14)
A15: Фотогенный рисунок / фотограмма | B15: =COUNTIF('01_Master_Facts'!$H$2:$H$800,A15) | D15: PL-006 | E15: =COUNTIF('01_Master_Facts'!$O$2:$O$800,D15)
A16: Негатив-позитив | B16: =COUNTIF('01_Master_Facts'!$H$2:$H$800,A16) | D16: PL-007 | E16: =COUNTIF('01_Master_Facts'!$O$2:$O$800,D16)
A17: Печать / тиражирование | B17: =COUNTIF('01_Master_Facts'!$H$2:$H$800,A17) | D17: PL-008 | E17: =COUNTIF('01_Master_Facts'!$O$2:$O$800,D17)
A18: Уникальный позитив | B18: =COUNTIF('01_Master_Facts'!$H$2:$H$800,A18) | D18: PL-009 | E18: =COUNTIF('01_Master_Facts'!$O$2:$O$800,D18)
A19: Цвет | B19: =COUNTIF('01_Master_Facts'!$H$2:$H$800,A19) | D19: PL-010 | E19: =COUNTIF('01_Master_Facts'!$O$2:$O$800,D19)
A20: Проекция / распространение | B20: =COUNTIF('01_Master_Facts'!$H$2:$H$800,A20) | D20: PL-011 | E20: =COUNTIF('01_Master_Facts'!$O$2:$O$800,D20)
A21: Цвет | B21: =COUNTIF('01_Master_Facts'!$H$2:$H$600,A21) | D21: PL-012 | E21: =COUNTIF('01_Master_Facts'!$O$2:$O$800,D21)
A22: Проекция / распространение | B22: =COUNTIF('01_Master_Facts'!$H$2:$H$600,A22) | D22: PL-013 | E22: =COUNTIF('01_Master_Facts'!$O$2:$O$800,D22)
D23: PL-014 | E23: =COUNTIF('01_Master_Facts'!$O$2:$O$800,D23)
D24: PL-015 | E24: =COUNTIF('01_Master_Facts'!$O$2:$O$800,D24)
D25: PL-016 | E25: =COUNTIF('01_Master_Facts'!$O$2:$O$800,D25)
D26: PL-017 | E26: =COUNTIF('01_Master_Facts'!$O$2:$O$800,D26)
D27: PL-018 | E27: =COUNTIF('01_Master_Facts'!$O$2:$O$800,D27)
D28: PL-019 | E28: =COUNTIF('01_Master_Facts'!$O$2:$O$800,D28)
D29: PL-020 | E29: =COUNTIF('01_Master_Facts'!$O$2:$O$800,D29)
D30: PL-021 | E30: =COUNTIF('01_Master_Facts'!$O$2:$O$800,D30)
D31: PL-022 | E31: =COUNTIF('01_Master_Facts'!$O$2:$O$800,D31)
D32: PL-023 | E32: =COUNTIF('01_Master_Facts'!$O$2:$O$800,D32)
D33: PL-024 | E33: =COUNTIF('01_Master_Facts'!$O$2:$O$800,D33)
D34: PL-025 | E34: =COUNTIF('01_Master_Facts'!$O$2:$O$800,D34)
... D54: PL-045 | E54: =COUNTIF('01_Master_Facts'!$O$2:$O$800,D54)
A55: Фундаментальная предпосылка | B55: =COUNTIF('01_Master_Facts'!$Z$2:$Z$800,"Фундаментальная предпосылка") | D55: PL-046 | E55: =COUNTIF('01_Master_Facts'!$O$2:$O$800,D55)
A56: Технология / процесс | B56: =COUNTIF('01_Master_Facts'!$Z$2:$Z$800,"Технология / процесс") | D56: будущие PL | E56: =COUNTIF('01_Master_Facts'!$O$2:$O$800,D56)
A57: Инструмент / устройство | B57: =COUNTIF('01_Master_Facts'!$Z$2:$Z$800,"Инструмент / устройство") | D57: межурочный узел | E57: =COUNTIF('01_Master_Facts'!$O$2:$O$800,D57)
A58: Публикация / объявление | B58: =COUNTIF('01_Master_Facts'!$Z$2:$Z$800,"Публикация / объявление")
A59: Терминология / язык | B59: =COUNTIF('01_Master_Facts'!$Z$2:$Z$800,"Терминология / язык")
A60: Связь / переход | B60: =COUNTIF('01_Master_Facts'!$Z$2:$Z$800,"Связь / переход")
A61: Тиражирование / публикация | B61: =COUNTIF('01_Master_Facts'!$Z$2:$Z$800,"Тиражирование / публикация")
...

Sheet 01_Master_Facts
A1: ID | B1: Период / дата | C1: Точность даты | D1: Страна | E1: Город / регион | F1: Персона / группа | G1: Событие | H1: Ветка развития | I1: Технология / процесс | J1: Что изменилось | K1: Предыдущая связь | L1: Следующая связь | M1: Статус ветки | N1: Важность 1–5 | O1: Привязка к уроку | P1: Источник ID | Q1: Название источника | R1: URL источника | S1: Уверенность 1–5 | T1: Комментарий для лекции | U1: Визуальная идея для карты | V1: Теги | W1: Проверить позже | X1: Координаты (lat, lon) | Y1: Подветка (детали) | Z1: Тип узла | AA1: Флагман урока (да/нет)
A2: PL-HIST-0001 | B2: ок. 1011–1021 | C2: диапазон | D2: Египет / исламский научный мир | E2: Каир / Басра (контекст учёного) | F2: Ибн аль-Хайсам (Альхазен) | G2: В «Книге оптики» системно исследует свет, зрение и опыт тёмной комнаты с малым отверстием. | H2: Оптика / камера-обскура | I2: Камера-обскура / pinhole image | J2: Фотографии ещё нет, но появляется научная база: свет распространяется прямыми линиями и может строить изображение. | K2: Античная оптика и астрономические наблюдения | L2: Европейская оптика, камера-обскура как инструмент наблюдения | M2: Оптическая предпосылка | N2: 5 | O2: PL-001 | P2: SRC-001 | Q2: AramcoWorld — Ibn al-Haytham: Testing is Believing | R2: https://www.aramcoworld.com/en/articles/2023/ibn-al-haytham-testing-is-believing | S2: 4 | T2: Важно сказать аккуратно: он не изобрёл фотографию, а дал фундамент для понимания изображения светом. | U2: Стартовая точка карты: луч света входит в тёмную комнату и строит перевёрнутое изображение. | V2: #оптика #камера-обскура #ИбнАльХайсам #PL001 | W2: Уточнить формулировку места: не привязывать к современной стране слишком жёстко. | X2: 30.0444, 31.2357 | Z2: Фундаментальная предпосылка | AA2: да
A3: PL-HIST-0002 | B3: 1545 | C3: год | D3: Нидерланды / Священная Римская империя | E3: Лёвен / Фрисландия (контекст публикации) | F3: Гемма Фризиус | G3: Публикует один из ранних известных рисунков камеры-обскуры, использованной для наблюдения солнечного затмения. | H3: Оптика / камера-обскура | I3: Камера-обскура как астрономический инструмент | J3: Принцип тёмной комнаты становится не только философским описанием, но и изображаемым инструментом наблюдения. | K3: Ибн аль-Хайсам и средневековая оптика | L3: Линза и художественное применение камеры-обскуры | M3: Оптическая предпосылка | N3: 3 | O3: PL-001 | P3: SRC-003 | Q3: Max Planck Institute — Camera Obscura PDF | R3: https://www.mpiwg-berlin.mpg.de/sites/default/files/Preprints/P307.pdf | S3: 3 | T3: Можно использовать как промежуточный узел: камера-обскура служит не фотографии, а безопасному наблюдению солнца. | U3: Иконка солнечного затмения + тёмная комната. | V3: #оптика #астрономия #камера-обскура | W3: Нужен первичный источник/точная ссылка на публикацию Frisius. | X3: 50.8798, 4.7005 | Z3: Инструмент / устройство
A4: PL-HIST-0003 | B4: 1550 | C4: год | D4: Италия | E4: Павия / Италия | F4: Джероламо Кардано | G4: Описывает использование стеклянной линзы в камере-обскуре для улучшения изображения. | H4: Оптика / камера-обскура | I4: Линза в камере-обскуре | J4: Камера-обскура становится ближе к будущей камере: не просто отверстие, а оптическое формирование более яркого и резкого изображения. | K4: Пинхол / тёмная комната | L4: Della Porta и популяризация камеры-обскуры | M4: Оптическая предпосылка | N4: 4 | O4: PL-001 | P4: SRC-002 | Q4: IMSS / Museo Galileo — Camera Obscura | R4: https://redi.imss.fi.it/inventions/index.php/Camera_Obscura | S4: 4 | T4: Для новичка: отверстие даёт картинку, линза делает её ярче и удобнее. | U4: На линии добавить маленькую линзу перед тёмной комнатой. | V4: #оптика #линза #камера | X4: 45.1847, 9.1582 | Z4: Инструмент / устройство
A5: PL-HIST-0004 | B5: 1558 | C5: год | D5: Италия | E5: Неаполь | F5: Джамбаттиста делла Порта | G5: В «Magia Naturalis» описывает камеру-обскуру как зрелищный и практический инструмент наблюдения/рисования. | H5: Оптика / камера-обскура | I5: Камера-обскура как инструмент художника | J5: Камера-обскура входит в европейскую культуру изображения: становится помощником перспективы и точного рисунка. | K5: Кардано и линза | L5: Kepler, портативные камеры-обскуры | M5: Оптическая предпосылка | N5: 4 | O5: PL-001 | P5: SRC-002 | Q5: IMSS / Museo Galileo — Camera Obscura | R5: https://redi.imss.fi.it/inventions/index.php/Camera_Obscura | S5: 4 | T5: Здесь можно показать мост от науки к искусству: камера ещё не фотографирует, но уже помогает изображать реальность. | U5: Иконка художника, который обводит проекцию. | V5: #оптика #искусство #DellaPorta | X5: 40.8518, 14.2681 | Z5: Применение / жанр
A6: PL-HIST-0005 | B6: 1604 | C6: год | D6: Германия | E6: Прага / Линц (контекст Kepler) | F6: Иоганн Кеплер | G6: Использует/закрепляет термин «camera obscura» и анализирует формирование оптического изображения. | H6: Оптика / камера-обскура | I6: Camera obscura | J6: Понятие получает устойчивое научное имя и входит в язык оптики. | K6: Renaissance descriptions of camera obscura | L6: Kepler's Dioptrice and portable camera obscura | M6: Оптическая предпосылка | N6: 3 | O6: PL-001 | P6: SRC-003 | Q6: Max Planck Institute — Camera Obscura PDF | R6: https://www.mpiwg-berlin.mpg.de/sites/default/files/Preprints/P307.pdf | S6: 4 | T6: На карте можно показать, что слова тоже важны: когда явление получает имя, его проще передавать и развивать. | U6: Плашка-термин: CAMERA OBSCURA. | V6: #оптика #Kepler #термин | X6: 50.0755, 14.4378 | Y6: Оптика / терминология | Z6: Терминология / язык
A7: PL-HIST-0006 | B7: 1611 | C7: год | D7: Германия | E7: Линц / Прага | F7: Иоганн Кеплер | G7: В «Dioptrice» развивает понимание линз, проекции и улучшения изображения в оптических системах. | H7: Оптика / камера-обскура | I7: Линзовая камера-обскура | J7: Будущая камера всё больше зависит от оптики: линзы дают контроль над изображением. | K7: Термин camera obscura | L7: Портативные камеры-обскуры и объективы | M7: Оптическая предпосылка | N7: 4 | O7: PL-001 | P7: SRC-003 | Q7: Max Planck Institute — Camera Obscura PDF | R7: https://www.mpiwg-berlin.mpg.de/sites/default/files/Preprints/P307.pdf | S7: 3 | T7: Не перегружать урок формулами; объяснить как «переход от дырочки к оптической системе». | U7: Схема: отверстие → линза → более яркая проекция. | V7: #оптика #линзы #Kepler | W7: Подтвердить конкретные формулировки по первичному тексту Dioptrice. | X7: 48.3069, 14.2858 | Y7: Оптика / камера | Z7: Фундаментальная предпосылка
A8: PL-HIST-0007 | B8: ок. 1620 | C8: примерно | D8: Австрия / Германия | E8: Верхняя Австрия | F8: Иоганн Кеплер | G8: Использует переносную камеру-обскуру в виде палатки для наблюдения и зарисовок ландшафта. | H8: Оптические инструменты | I8: Портативная camera obscura | J8: Камера-обскура становится мобильной: это важный шаг к переносной камере. | K8: Линзовая камера-обскура | L8: Zahn and portable camera designs | M8: Оптическая предпосылка | N8: 3 | O8: PL-001 | P8: SRC-003 | Q8: Max Planck Institute — Camera Obscura PDF | R8: https://www.mpiwg-berlin.mpg.de/sites/default/files/Preprints/P307.pdf | S8: 3 | T8: Хороший визуальный эпизод для рилса: учёный в тёмной палатке ловит изображение мира. | U8: Карта: линия от комнаты к переносной палатке. | V8: #камера-обскура #портативность #Kepler | W8: Проверить год и источники письма Henry Wotton. | X8: 48.3069, 14.2858 | Z8: Инструмент / устройство
A9: PL-HIST-0008 | B9: 1685 | C9: год | D9: Германия | E9: Вюрцбург | F9: Иоганн Цан | G9: Публикует схемы переносных камер-обскур и оптических устройств в «Oculus Artificialis». | H9: Оптические инструменты | I9: Портативная / зеркальная camera obscura | J9: Идея камеры становится почти предметной: устройство уже похоже на будущий фотоаппарат, но без химической фиксации. | K9: Портативные камеры-обскуры XVII века | L9: Фотохимия XVIII века | M9: Оптическая предпосылка | N9: 4 | O9: PL-001 | P9: SRC-004 | Q9: Public Domain Review — Johann Zahn's Oculus Artificialis | R9: https://publicdomainreview.org/collection/images-from-johann-zahn-s-oculus-artificialis-1685 | S9: 4 | T9: Можно показать как «корпус камеры появился раньше фотографии». | U9: Иконка деревянной камеры с зеркалом. | V9: #камера #Zahn #оптика | X9: 49.7913, 9.9534 | Z9: Инструмент / устройство
A10: PL-HIST-0009 | B10: 1727 | C10: год | D10: Германия | E10: Альтдорф / Галле | F10: Иоганн Генрих Шульце | G10: Публикует научное исследование: соли серебра темнеют под действием света, а не тепла. | H10: Фотохимия | I10: Серебряные соли | J10: Появляется химическая половина фотографии: материал может реагировать на свет. | K10: Алхимические наблюдения потемнения серебра | L10: Scheele, Wedgwood, Niépce | M10: Химическая предпосылка | N10: 5 | O10: PL-002 | P10: SRC-005 | Q10: Swiss Camera Museum — Johann Heinrich Schulze | R10: https://www.cameramuseum.ch/en/discover/permanent-exhibition/the-origins-of-photography/the-precursors-johann-heinrich-schulze/ | S10: 5 | T10: Это ключевой мост: камера уже строила изображение, но теперь появился материал, который свет может менять. | U10: Серебряная колба/бутылка, на которой свет оставляет след. | V10: #фотохимия #серебро #Schulze #PL002 | X10: 49.3833, 11.3833 | Z10: Фундаментальная предпосылка
A11: PL-HIST-0010 | B11: 1777 | C11: год | D11: Швеция | E11: Кёпинг / Стокгольм (контекст) | F11: Карл Вильгельм Шееле | G11: Изучает свойства хлорида серебра: потемнение на свету и роль аммиака для растворения/стабилизации соединений серебра. | H11: Фотохимия | I11: Silver chloride / ammonia | J11: Фиксация становится главным нерешённым вопросом: как сделать след света устойчивым. | K11: Schulze and silver salts | L11: Wedgwood and Davy, then Niépce | M11: Химическая предпосылка | N11: 4 | O11: PL-002 | P11: SRC-006 | Q11: Science History Institute — Silver and Sunlight | R11: https://www.sciencehistory.org/stories/magazine/silver-and-sunlight/ | S11: 4 | T11: Новичку объяснить: мало получить изображение — нужно остановить дальнейшее потемнение. | U11: Иконка: след света + знак «зафиксировать». | V11: #фотохимия #фиксаж #серебро | W11: Уточнить связь Scheele с практическим фиксированием: не преувеличивать. | X11: 59.5117, 15.9992 | Y11: Фотохимия / фиксация | Z11: Фундаментальная предпосылка
A12: PL-HIST-0011 | B12: ок. 1800 | C12: примерно | D12: Великобритания | E12: Этрурия / Стаффордшир | F12: Томас Веджвуд | G12: Проводит опыты с бумагой/кожей, обработанными нитратом серебра, пытаясь получать изображения светом. | H12: Фотохимия | I12: Серебряный нитрат на бумаге/коже | J12: Появляется идея фотографического изображения, но проблема сохранения ещё не решена. | K12: Schulze and Scheele | L12: Davy publication, Niépce's experiments | M12: Тупиковая / не получила развития | N12: 4 | O12: PL-002 | P12: SRC-007 | Q12: Swiss Camera Museum — Thomas Wedgwood | R12: https://www.cameramuseum.ch/en/discover/permanent-exhibition/the-origins-of-photography/the-precursors-thomas-wedgwood/ | S12: 4 | T12: Хорошо показать как честную неудачу: попытка почти фотографическая, но изображение исчезает. | U12: Пунктирная линия: «почти получилось, но не закрепилось». | V12: #Wedgwood #фотохимия #неудача | X12: 53.0027, -2.1794 | Y12: Фотохимия / первая фиксация | Z12: Технология / процесс
A13: PL-HIST-0012 | B13: 1802 | C13: год | D13: Великобритания | E13: Лондон / Бристоль | F13: Хамфри Дэви и Томас Веджвуд | G13: Дэви публикует отчёт о методе копирования изображений светом на нитрате серебра. | H13: Фотохимия | I13: Photogenic copying on silver nitrate | J13: Первые эксперименты становятся опубликованным знанием, но без полноценного фиксирования изображения. | K13: Wedgwood experiments | L13: Niépce and Talbot later address permanence | M13: Тупиковая / не получила развития | N13: 4 | O13: PL-002 | P13: SRC-008 | Q13: Bodleian — Talbot Catalogue: Photogenic Drawing | R13: https://talbot.bodleian.ox.ac.uk/2017/02/17/an-account-of-the-processes-employed-in-photogenic-drawing/ | S13: 4 | T13: В лекции: до Ньепса уже были люди, которые понимали направление, но не решили задачу постоянства. | U13: Иконка публикации/лист бумаги, который постепенно темнеет. | V13: #Davy #Wedgwood #публикация | W13: Добавить первичный PDF/текст Journal of the Royal Institution при углублении. | X13: 51.5074, -0.1278 | Y13: Фотохимия / публикация | Z13: Публикация / объявление
A14: PL-HIST-0013 | B14: 1806–1807 | C14: диапазон | D14: Великобритания | E14: Лондон | F14: Уильям Хайд Волластон | G14: Патентует и называет camera lucida — оптический прибор для точного рисования. | H14: Оптические инструменты | I14: Camera lucida | J14: Показывает, что до фотографии общество уже искало способы механизировать точность изображения. | K14: Camera obscura drawing tools | L14: Photography will replace drawing aids for some purposes | M14: Оптическая предпосылка | N14: 3 | O14: межурочный узел | P14: SRC-009 | Q14: Smithsonian NMAH — Camera Lucida | R14: https://americanhistory.si.edu/collections/object/nmah_1184286 | S14: 5 | T14: Это не фотография, но очень полезный узел: люди хотели точного изображения до химической фотографии. | U14: Иконка призмы и руки художника. | V14: #оптика #camera-lucida #рисование | X14: 51.5074, -0.1278 | Z14: Инструмент / устройство
A15: PL-HIST-0014 | B15: 1816 | C15: год | D15: Франция | E15: Сен-Лу-де-Варенн / Ле-Гра | F15: Нисефор Ньепс | G15: Получает исчезающие негативные изображения в камере-обскуре на бумаге с солями серебра. | H15: Гелиография | I15: Silver chloride paper negative | J15: Ньепс впервые подходит к реальной камере-фотографии, но изображение ещё не устойчиво. | K15: Wedgwood/Davy experiments | L15: Niépce switches to bitumen heliography | M15: Переходная технология | N15: 5 | O15: PL-002 | P15: SRC-011 | Q15: Maison Nicéphore Niépce — First experiments | R15: https://bicentennial-of-photography.org/niepce-and-the-invention-of-photography-niepce-s-first-experiments/ | S15: 4 | T15: Важно: это не первый сохранившийся снимок, а первая стадия Ньепса — изображение было, но исчезало. | U15: Светлая линия появляется на бумаге и затем исчезает. | V15: #Niépce #1816 #PL002 #негатив | X15: 46.7828, 4.8892 | Y15: Первая фиксация / проблема постоянства | Z15: Технология / процесс
A16: PL-HIST-0015 | B16: 1822–1825 | C16: диапазон | D16: Франция | E16: Сен-Лу-де-Варенн / Ле-Гра | F16: Нисефор Ньепс | G16: Развивает гелиографию: использует светочувствительный битум для создания устойчивых изображений/копий гравюр. | H16: Гелиография | I16: Bitumen of Judea on metal/stone | J16: Путь меняется: вместо серебряных солей Ньепс ищет материал, который свет делает не темнее, а твёрже/нерастворимее. | K16: 1816 silver-salt negatives | L16: View from the Window at Le Gras | M16: Переходная технология | N16: 4 | O16: PL-002 | P16: SRC-010 | Q16: Harry Ransom Center — The Niépce Heliograph | R16: https://www.hrc.utexas.edu/niepce-heliograph/ | S16: 4 | T16: Для лекции: Ньепс думал не только о камере, но и о механическом копировании изображений. | U16: Узел «гелиография»: солнце превращает покрытие в устойчивый след. | V16: #гелиография #Niépce #битум | W16: Проверить дату 1822 для несохранившейся heliograph copy. | X16: 46.7828, 4.8892 | Z16: Технология / процесс
A17: PL-HIST-0016 | B17: 1826 / 1827 | C17: спорно/уточнить | D17: Франция | E17: Ле-Гра, Сен-Лу-де-Варенн | F17: Нисефор Ньепс | G17: Создаёт «Вид из окна в Ле-Гра» — самое раннее сохранившееся изображение, полученное с помощью камеры-обскуры. | H17: Гелиография | I17: Heliograph on pewter plate | J17: Изображение впервые не просто возникло, а сохранилось до наших дней. | K17: Heliographic experiments | L17: Partnership with Daguerre | M17: Главная линия | N17: 5 | O17: PL-002 | P17: SRC-010 | Q17: Harry Ransom Center — The Niépce Heliograph | R17: https://www.hrc.utexas.edu/niepce-heliograph/ | S17: 5 | T17: Дата встречается как 1826 или 1827; в таблице оставляем спорной/уточняемой. | U17: Главный узел PL-002: окно, свет, металлическая пластина. | V17: #Niépce #перваяфотография #гелиография #PL002 | W17: Уточнить редакционную дату: Harvard даёт 1826, HRC — 1827. | X17: 46.7828, 4.8892 | Y17: Гелиография / первая сохранившаяся фотография | Z17: Ключевой исторический узел | AA17: да
A18: PL-HIST-0017 | B18: 1829 | C18: год | D18: Франция | E18: Париж / Сен-Лу-де-Варенн | F18: Нисефор Ньепс и Луи Дагер | G18: Ньепс и Дагер вступают в формальное партнёрство для развития фотографического процесса. | H18: Дагеротип | I18: Heliography → daguerreotype lineage | J18: Линия Ньепса соединяется с практическими улучшениями Дагера. | K18: Niépce heliography | L18: Daguerreotype announcement | M18: Главная линия | N18: 4 | O18: PL-003 | P18: SRC-010 | Q18: Harry Ransom Center — The Niépce Heliograph | R18: https://www.hrc.utexas.edu/niepce-heliograph/ | S18: 5 | T18: Это не просто смена фамилии: здесь начинается связка Ньепс → Дагер. | U18: Линия на карте: Ле-Гра → Париж. | V18: #Niépce #Daguerre #Франция #PL003 | X18: 48.8566, 2.3522 | Y18: Передача идеи / развитие процесса | Z18: Связь / переход
A19: PL-HIST-0018 | B19: 1833 | C19: год | D19: Франция | E19: Сен-Лу-де-Варенн | F19: Нисефор Ньепс / Луи Дагер | G19: После смерти Ньепса Дагер продолжает работы и в итоге доводит процесс до публичного объявления. | H19: Дагеротип | I19: Daguerreotype lineage | J19: Фотография становится историей не одного человека, а продолжения незавершённой разработки. | K19: Partnership 1829 | L19: 1839 public announcement | M19: Главная линия | N19: 3 | O19: PL-003 | P19: SRC-010 | Q19: Harry Ransom Center — The Niépce Heliograph | R19: https://www.hrc.utexas.edu/niepce-heliograph/ | S19: 4 | T19: Для сериала: Ньепс не увидел публичного триумфа фотографии. | U19: Линия прерывается у Ньепса и продолжается к Дагеру. | V19: #Niépce #Daguerre #история | X19: 46.7828, 4.8892 | Y19: Передача идеи / развитие процесса | Z19: Связь / переход
A20: PL-HIST-0019 | B20: 1834 | C20: год | D20: Великобритания | E20: Лэкок-Эбби | F20: Уильям Генри Фокс Тальбот | G20: Создаёт фотогенные рисунки: предметы кладутся на светочувствительную бумагу и оставляют силуэт. | H20: Фотогенный рисунок / фотограмма | I20: Photogenic drawing | J20: Параллельно французской линии появляется британская ветка: изображение через негативный след на бумаге. | K20: Wedgwood/Davy and silver salts | L20: Calotype and negative-positive process | M20: Главная линия | N20: 5 | O20: PL-004 | P20: SRC-023 | Q20: National Gallery of Canada — The Calotype Process | R20: https://www.gallery.ca/photo-blog/the-calotype-process | S20: 4 | T20: Важно показать как параллельную работу, а не как продолжение Дагера. | U20: Отдельная линия Великобритания: лист растения на бумаге. | V20: #Talbot #photogenic-drawing #PL004 | X20: 51.4136, -2.118 | Z20: Технология / процесс
A21: PL-HIST-0020 | B21: 1835 | C21: год | D21: Великобритания | E21: Лэкок-Эбби | F21: Уильям Генри Фокс Тальбот | G21: Делает ранние маленькие камерные негативы, включая вид окна в Лэкок-Эбби. | H21: Негатив-позитив | I21: Paper negative in camera | J21: Тальбот переносит идею фотогенного рисунка в камеру: бумага становится негативом будущей копии. | K21: Photogenic drawings | L21: 1839 publication and 1841 calotype | M21: Главная линия | N21: 4 | O21: PL-004 | P21: SRC-016 | Q21: The Met — William Henry Fox Talbot | R21: https://www.metmuseum.org/essays/william-henry-fox-talbot-1800-1877-and-the-invention-of-photography | S21: 4 | T21: Можно объяснить: у Тальбота фотография думает не как «одна пластинка», а как система копирования. | U21: Окно Лэкок-Эбби как британская пара к окну Ньепса. | V21: #Talbot #окно #негатив #PL004 | W21: Проверить источник для конкретной даты и объекта Oriel Window. | X21: 51.4136, -2.118 | Z21: Технология / процесс
A22: PL-HIST-0021 | B22: 1837 | C22: год | D22: Франция | E22: Париж | F22: Луи Дагер | G22: Дагер получает более практичный прямой позитив на серебряной пластине и сокращает экспозицию по сравнению с Ньепсом. | H22: Дагеротип | I22: Silver-plated copper plate / direct positive | J22: Фотография становится резче, быстрее и технически убедительнее, но остаётся уникальным изображением. | K22: Niépce-Daguerre partnership | L22: 1839 Académie announcement | M22: Исторически важная ограниченная ветка | N22: 4 | O22: PL-003 | P22: SRC-013 | Q22: The Met — Daguerre and the Invention of Photography | R22: https://www.metmuseum.org/essays/daguerre-1787-1851-and-the-invention-of-photography | S22: 3 | T22: В таблице фиксируем как техническую подготовку к публичному объявлению, но дату/детали уточнить. | U22: Металлическая пластина + резкое изображение. | V22: #Daguerre #дагеротип #PL003 | W22: Уточнить первичный источник и дату 1837. | X22: 48.8566, 2.3522 | Z22: Технология / процесс | AA22: да
A23: PL-HIST-0022 | B23: 7 января 1839 | C23: точная дата | D23: Франция | E23: Париж | F23: Франсуа Араго / Луи Дагер | G23: Французская Академия наук видит результаты процесса Дагера; фотография выходит в публичное научное поле. | H23: Дагеротип | I23: Daguerreotype | J23: Фотография перестаёт быть частной лабораторной тайной и становится событием культуры и науки. | K23: Daguerre's experiments | L23: 19 August 1839 public disclosure | M23: Временная доминирующая линия | N23: 5 | O23: PL-003 | P23: SRC-013 | Q23: The Met — Daguerre and the Invention of Photography | R23: https://www.metmuseum.org/essays/daguerre-1787-1851-and-the-invention-of-photography | S23: 5 | T23: Это сильная сцена: не просто изобретение, а момент публичного признания. | U23: Париж, Академия наук, световая демонстрация. | V23: #Daguerre #Arago #Париж #PL003 | X23: 48.8566, 2.3522 | Y23: Дагеротип / публичное объявление | Z23: Публикация / объявление
A24: PL-HIST-0023 | B24: 19 августа 1839 | C24: точная дата | D24: Франция | E24: Париж | F24: Луи Дагер / французское государство | G24: Процесс дагеротипии официально раскрывается публично; Франция фактически дарит процесс миру. | H24: Дагеротип | I24: Daguerreotype | J24: Дагеротип быстро распространяется по Европе и Америке как первый публично объявленный фотографический процесс. | K24: Academy announcement | L24: Daguerreotypomania and portrait studios | M24: Временная доминирующая линия | N24: 5 | O24: PL-003 | P24: SRC-012 | Q24: Harvard Library — History of Photography Timeline | R24: https://photographpreservationprogram.hsites.harvard.edu/harvards-history-photography-timeline-text-only | S24: 5 | T24: В уроке: 1839 — год, когда фотография стала общественным событием. | U24: Большая точка на Париже и расходящиеся линии по миру. | V24: #1839 #Daguerre #Франция #распространение | X24: 48.8566, 2.3522 | Y24: Дагеротип / распространение | Z24: Публикация / объявление
A25: PL-HIST-0024 | B25: 1839 | C25: год | D25: Великобритания | E25: Лондон | F25: Уильям Генри Фокс Тальбот | G25: Публикует «Some Account of the Art of Photogenic Drawing», представляя свой процесс. | H25: Фотогенный рисунок / фотограмма | I25: Photogenic drawing | J25: Британская линия заявляет о себе почти одновременно с французской, показывая параллельность изобретения фотографии. | K25: 1834–1835 experiments | L25: Calotype patent 1841 | M25: Главная линия | N25: 5 | O25: PL-004 | P25: SRC-012 | Q25: Harvard Library — History of Photography Timeline | R25: https://photographpreservationprogram.hsites.harvard.edu/harvards-history-photography-timeline-text-only | S25: 5 | T25: Идеально для объяснения: Франция дала резкость и публичный эффект, Британия — логику копии. | U25: Две линии на карте: Париж и Лондон одновременно загораются в 1839. | V25: #Talbot #1839 #PL004 | X25: 51.5074, -0.1278 | Y25: Фотогенный рисунок / публикация | Z25: Публикация / объявление
A26: PL-HIST-0025 | B26: 1839 | C26: год | D26: Великобритания | E26: Лондон / Slough | F26: Джон Фредерик Уильям Гершель | G26: Предлагает использовать hyposulphite of soda как фиксирующее средство для серебряных фотографий. | H26: Фиксаж / терминология | I26: Hypo / sodium thiosulfate fixer | J26: Фотография становится практически долговечной: изображение можно остановить от дальнейшего действия света. | K26: Silver-salt image instability | L26: Stable calotypes and later silver processes | M26: Главная линия | N26: 5 | O26: PL-004 | P26: SRC-016 | Q26: The Met — William Henry Fox Talbot | R26: https://www.metmuseum.org/essays/william-henry-fox-talbot-1800-1877-and-the-invention-of-photography | S26: 5 | T26: Сильный смысл: фотография — это не только камера, но и умение остановить свет. | U26: Иконка замка/стоп-символа на изображении. | V26: #Herschel #фиксаж #hypo | X26: 51.5074, -0.1278 | Z26: Технология / процесс
A27: PL-HIST-0026 | B27: 1839 | C27: год | D27: Великобритания | E27: Лондон | F27: Джон Фредерик Уильям Гершель | G27: Вводит/закрепляет термины «photography», «negative» и «positive» в ранней фотографической культуре. | H27: Фиксаж / терминология | I27: Photographic terminology | J27: Язык фотографии формируется: появляются термины, без которых невозможно объяснить негативно-позитивный процесс. | K27: Talbot's paper negatives and photogenic drawings | L27: Calotype and photographic vocabulary | M27: Главная линия | N27: 4 | O27: PL-004 | P27: SRC-017 | Q27: Getty — Sir John F. W. Herschel | R27: https://www.getty.edu/art/collection/person/103KHK | S27: 4 | T27: Можно сделать мини-вставку: терминология — это тоже технология понимания. | U27: Карточка слов: PHOTOGRAPHY / NEGATIVE / POSITIVE. | V27: #Herschel #термины #negative #positive | W27: Уточнить первичные даты употребления терминов в письмах/докладах. | X27: 51.5074, -0.1278 | Z27: Терминология / язык
A28: PL-HIST-0027 | B28: 1839–1840 | C28: диапазон | D28: Франция | E28: Париж | F28: Ипполит Байяр | G28: Разрабатывает прямой позитивный процесс на бумаге, но оказывается в тени Дагера и Тальбота. | H28: Уникальный позитив | I28: Direct positive paper process | J28: Показывает, что история фотографии была многоголосой: не все ветки получили признание и масштаб. | K28: French early photographic experiments | L28: Bayard's staged self-portrait and later history | M28: Исторически важная ограниченная ветка | N28: 3 | O28: межурочный узел | P28: SRC-017 | Q28: Getty — Sir John F. W. Herschel | R28: https://www.getty.edu/art/collection/person/103KHK | S28: 3 | T28: Можно использовать как сюжет о несправедливости истории и «забытых изобретателях». | U28: Пунктирная ветка от Парижа, уходящая в сторону. | V28: #Bayard #direct-positive #забытые | W28: Найти лучший источник именно по процессу Байяра, не только биографию Getty. | X28: 48.8566, 2.3522 | Z28: Технология / процесс
A29: PL-HIST-0028 | B29: 1838 | C29: год | D29: Великобритания | E29: Лондон | F29: Чарльз Уитстон | G29: Представляет стереоскоп и демонстрирует принцип бинокулярного зрения. | H29: Оптические инструменты | I29: Stereoscope | J29: Пока ещё не фотографическая технология, но позже стереофотография станет массовой формой визуального опыта. | K29: Optics of vision | L29: Photographic stereographs in the 1850s | M29: Оптическая предпосылка | N29: 3 | O29: будущие PL | P29: SRC-024 | Q29: Royal Society / Google Arts & Culture — Stereoscopy | R29: https://artsandculture.google.com/story/stereoscopy-the-birth-of-3d-technology-the-royal-society/pwWRTNS-hqDN5g | S29: 4 | T29: Этот узел лучше оставить для будущего раздела о 3D/стереофотографии. | U29: Иконка двух глаз / двух изображений. | V29: #стереоскоп #Wheatstone #3D | X29: 51.5074, -0.1278 | Y29: Оптические инструменты / 3D | Z29: Инструмент / устройство
A30: PL-HIST-0029 | B30: 1840 | C30: год | D30: Великобритания | E30: Лэкок-Эбби | F30: Уильям Генри Фокс Тальбот | G30: Обнаруживает латентное изображение и проявление галловой кислотой: секунды экспозиции дают скрытый след, который можно проявить. | H30: Негатив-позитив | I30: Latent image development | J30: Это резко ускоряет бумажную фотографию: теперь не нужно ждать видимого потемнения во время экспозиции. | K30: Photogenic drawing and camera negatives | L30: Calotype patent 1841 | M30: Главная линия | N30: 5 | O30: PL-004 | P30: SRC-016 | Q30: The Met — William Henry Fox Talbot | R30: https://www.metmuseum.org/essays/william-henry-fox-talbot-1800-1877-and-the-invention-of-photography | S30: 5 | T30: Для новичка: фотография научилась работать со скрытым изображением. | U30: Схема: невидимый след → проявитель → появляется картинка. | V30: #latent-image #Talbot #PL004 | X30: 51.4136, -2.118 | Y30: Негатив-позитив / проявление | Z30: Технология / процесс
A31: PL-HIST-0030 | B31: 1840 | C31: год | D31: США | E31: Нью-Йорк | F31: Джон Уильям Дрейпер | G31: Делает ранние научные дагеротипы, включая одну из первых фотографий Луны. | H31: Дагеротип | I31: Daguerreotype for astronomy | J31: Фотография быстро выходит за пределы портрета и становится научным инструментом. | K31: Daguerreotype public disclosure | L31: Astronomical and scientific photography | M31: Главная линия | N31: 3 | O31: будущие PL | P31: SRC-012 | Q31: Harvard Library — History of Photography Timeline | R31: https://photographpreservationprogram.hsites.harvard.edu/harvards-history-photography-timeline-text-only | S31: 3 | T31: Будущий узел для урока о научной фотографии. | U31: Линия Париж → Нью-Йорк + Луна. | V31: #Draper #астрономия #научнаяфотография | W31: Добавить более авторитетный музейный источник по Draper. | Ветка нормализована к 13 значениям v0.2 — узел межжанровый, решение неоднозначное (см. Подветка). | X31: 40.7128, -74.006 | Y31: Научная фотография | Z31: Научное применение / пример
A32: PL-HIST-0031 | B32: 1841 | C32: год | D32: Великобритания | E32: Лондон / Лэкок-Эбби | F32: Уильям Генри Фокс Тальбот | G32: Патентует калотип: усовершенствованный негативно-позитивный процесс на бумаге. | H32: Негатив-позитив | I32: Calotype / Talbotype | J32: Появляется фундаментальная логика фотографии: один негатив может дать много позитивных отпечатков. | K32: Latent image development 1840 | L32: Salted paper prints and The Pencil of Nature | M32: Главная линия | N32: 5 | O32: PL-004 | P32: SRC-015 | Q32: Library of Congress — Calotype and Daguerreotype | R32: https://blogs.loc.gov/teachers/2018/09/pre-civil-war-photographic-technologies-the-calotype-and-daguerreotype/ | S32: 5 | T32: Ключевой тезис PL-004: калотип менее резкий, чем дагеротип, но его идея победила. | U32: Разветвление: один негатив → несколько отпечатков. | V32: #calotype #Talbot #negative-positive #PL004 | X32: 51.5074, -0.1278 | Z32: Технология / процесс | AA32: да
A33: PL-HIST-0032 | B33: 1841 | C33: год | D33: Великобритания | E33: Лондон / Лэкок-Эбби | F33: Уильям Генри Фокс Тальбот | G33: Солёная бумажная печать становится практическим позитивом с бумажного негатива. | H33: Печать / тиражирование | I33: Salted paper print | J33: Фотография становится печатной системой: негатив и позитив начинают работать вместе. | K33: Calotype negative | L33: Pencil of Nature and albumen print | M33: Главная линия | N33: 4 | O33: PL-004 | P33: SRC-020 | Q33: V&A — Photography Processes and Techniques | R33: https://www.vam.ac.uk/info/collection-selection-boxes-photography-processes-and-techniques | S33: 4 | T33: Для схемы: калотип — это не только негатив, но и контактная печать. | U33: Контактная рамка: негатив лежит на бумаге под стеклом. | V33: #salted-paper #print #Talbot | X33: 51.5074, -0.1278 | Z33: Тиражирование / публикация
A34: PL-HIST-0033 | B34: 1842 | C34: год | D34: Великобритания | E34: Лондон / Slough | F34: Джон Фредерик Уильям Гершель | G34: Изобретает цианотипию — железо-солевой процесс, дающий синий отпечаток. | H34: Печать / тиражирование | I34: Cyanotype | J34: Показывает, что фотография не обязана быть только серебряной; появляется альтернативная печать и будущие blueprint-процессы. | K34: Herschel's photochemistry | L34: Anna Atkins's photographic book | M34: Переходная технология / художественное возрождение | N34: 4 | O34: будущие PL | P34: SRC-018 | Q34: HNOC — Cyanotype Process | R34: https://hnoc.org/virtual-exhibitions/from_daguerreotype_to_digital/cyanotype-process | S34: 5 | T34: Цианотипия идеальна для практического урока: простой, зрелищный процесс. | U34: Синяя ветка на карте. | V34: #cyanotype #Herschel #альтернативныйпроцесс | W34: Ветка нормализована к 13 значениям v0.2 — узел межжанровый, решение неоднозначное (см. Подветка). | X34: 51.5074, -0.1278 | Y34: Цианотипия | Z34: Технология / процесс
A35: PL-HIST-0034 | B35: 1843 | C35: год | D35: Великобритания | E35: Кент | F35: Анна Аткинс | G35: Начинает выпуск «Photographs of British Algae: Cyanotype Impressions» — первой книги, напечатанной и иллюстрированной фотографией. | H35: Печать / тиражирование | I35: Cyanotype photobook | J35: Фотография становится способом научной публикации, а не только экспериментом или портретом. | K35: Cyanotype 1842 | L35: Scientific and documentary photography | M35: Главная линия | N35: 4 | O35: будущие PL | P35: SRC-019 | Q35: Natural History Museum — Anna Atkins's cyanotypes | R35: https://www.nhm.ac.uk/discover/anna-atkins-cyanotypes-the-first-book-of-photographs.html | S35: 5 | T35: Очень важный узел: женщина-фотограф, наука, книга и фотография как документ. | U35: Иконка синей книги с водорослью. | V35: #AnnaAtkins #cyanotype #photobook | X35: 51.2787, 0.5217 | Y35: Фотокнига / научная документация | Z35: Тиражирование / публикация
A36: PL-HIST-0035 | B36: 1844 | C36: год | D36: Великобритания | E36: Лондон | F36: Уильям Генри Фокс Тальбот | G36: Начинает публикацию «The Pencil of Nature» — первой коммерчески изданной книги с фотографическими отпечатками. | H36: Печать / тиражирование | I36: Salted paper prints from calotype negatives | J36: Фотография входит в книгу как новый способ иллюстрации и доказательства. | K36: Calotype and salted paper print | L36: Photographic publishing | M36: Главная линия | N36: 5 | O36: PL-004 | P36: SRC-016 | Q36: The Met — William Henry Fox Talbot | R36: https://www.metmuseum.org/essays/william-henry-fox-talbot-1800-1877-and-the-invention-of-photography | S36: 5 | T36: Сильный мост к бренду PHOTO LAB: фотография становится не только снимком, но и системой распространения знания. | U36: Книга, из которой выходят маленькие отпечатки. | V36: #PencilOfNature #Talbot #книга #PL004 | X36: 51.5074, -0.1278 | Y36: Фотокнига / тиражирование | Z36: Тиражирование / публикация
A37: PL-HIST-0036 | B37: 1847 | C37: год | D37: США | E37: Бостон | F37: Southworth & Hawes | G37: Создают дагеротипы медицинских операций с эфирной анестезией в Massachusetts General Hospital. | H37: Дагеротип | I37: Daguerreotype documentation | J37: Фотография быстро становится инструментом медицинского и научного свидетельства. | K37: Daguerreotype portrait/studio practice | L37: Documentary and medical photography | M37: Главная линия | N37: 3 | O37: будущие PL | P37: SRC-012 | Q37: Harvard Library — History of Photography Timeline | R37: https://photographpreservationprogram.hsites.harvard.edu/harvards-history-photography-timeline-text-only | S37: 4 | T37: Этот узел можно оставить для будущего урока о документальности фотографии. | U37: Иконка больницы/операционной + дагеротип. | V37: #medical-photography #daguerreotype #Boston | W37: Ветка нормализована к 13 значениям v0.2 — узел межжанровый, решение неоднозначное (см. Подветка). | X37: 42.3601, -71.0589 | Y37: Научная / медицинская фотография | Z37: Научное применение / пример
A38: PL-HIST-0037 | B38: 1847 | C38: год | D38: Франция | E38: Лилль / Париж | F38: Луи-Дезире Бланкар-Эврар | G38: Развивает и публикует улучшения бумажных негативно-позитивных процессов во Франции. | H38: Печать / тиражирование | I38: Paper negative-positive process | J38: Французская фотография получает не только дагеротипическую, но и бумажную тиражируемую ветку. | K38: Talbot calotype influence | L38: Albumen paper 1850 | M38: Главная линия | N38: 3 | O38: будущие PL | P38: SRC-017 | Q38: Getty — Sir John F. W. Herschel | R38: https://www.getty.edu/art/collection/person/103KHK | S38: 2 | T38: Пока источник не идеален; оставить как узел на доработку. | U38: Франция получает ответвление бумажной печати. | V38: #BlanquartEvrard #France #paper-process | W38: Найти лучший источник по 1847 публикации Бланкара-Эврара. | X38: 50.6292, 3.0573 | Z38: Распространение / коммерциализация
A39: PL-HIST-0038 | B39: 1848 | C39: год | D39: Франция | E39: Париж | F39: Эдмон Беккерель | G39: Создаёт ранний цветной фотографический процесс на основе серебряно-хлоридного слоя. | H39: Цвет | I39: Early colour photography / photochromatic images | J39: Цвет возникает очень рано, но эта ветка пока не становится практичной массовой фотографией. | K39: Silver-based photochemistry | L39: Autochrome and later colour processes | M39: Исторически важная ограниченная ветка | N39: 3 | O39: будущие PL | P39: SRC-025 | Q39: Getty Conservation Institute — Atlas: Salt Print PDF | R39: https://www.getty.edu/conservation/publications_resources/pdf_publications/pdf/atlas_saltprint.pdf | S39: 3 | T39: На карте: цвет появился рано, но не сразу стал удобным. | U39: Пунктирная цветная ветка от серебряной химии. | V39: #color #Becquerel #раннийцвет | W39: Лучше заменить на специализированный музейный источник по Becquerel. | X39: 48.8566, 2.3522 | Z39: Технология / процесс
A40: PL-HIST-0039 | B40: 1848 | C40: год | D40: США | E40: Филадельфия | F40: Братья Лангенхайм | G40: Вводят первые фотографические фонарные слайды. | H40: Проекция / распространение | I40: Photographic lantern slide | J40: Фотография становится не только отпечатком, но и изображением для публичного показа и обучения. | K40: Daguerreotype and glass support experimentation | L40: Educational projection and slide culture | M40: Переходная технология | N40: 3 | O40: будущие PL | P40: SRC-012 | Q40: Harvard Library — History of Photography Timeline | R40: https://photographpreservationprogram.hsites.harvard.edu/harvards-history-photography-timeline-text-only | S40: 4 | T40: Хороший узел для темы распространения изображений до кино и презентаций. | U40: Фонарный проектор + экран. | V40: #lantern-slide #projection #Langenheim | X40: 39.9526, -75.1652 | Z40: Распространение / коммерциализация
...

Sheet 02_Branches
A1: Ветка | B1: Что включает | C1: Для каких уроков | D1: Визуальный цвет/код | E1: Комментарий
A2: Оптика / камера-обскура | B2: свет, тёмная комната, pinhole, линзы | C2: PL-001 | D2: синий | E2: Это предпосылка фотографии, не сама фотография.
A3: Оптические инструменты | B3: camera lucida, stereoscope, portable camera obscura, compact 35mm cameras, Leica I, Leica system, rangefinder lineage, SLR, TLR, compact point-and-shoot, средний формат, большой формат, view camera, устройство плёночной камеры, выбор первой камеры, авторская роль камеры, объектив, элементы объектива, байонет, диафрагма, фокусное расстояние, угол зрения, широкий угол, нормальный 50 мм, портретный объектив, телеобъектив, светосила, диафрагма, базовая экспозиция, диафрагма как окно, выдержка как время, ISO как чувствительность, экспозиционный треугольник, стопы света | C3: PL-001 / PL-009 / PL-010 / PL-021–PL-039 / PL-041–PL-046 / будущие PL | D3: голубой | E3: Оптическая и камерная линия: от оптических предпосылок к устройству камеры, объективам, типам фокусных расстояний и управлению экспозицией через диафрагму, выдержку, ISO и стопы света.
A4: Фотохимия | B4: серебряные соли, желатиновые эмульсии, скрытое изображение, проявление, чувствительность, ISO / film speed, EI, push/pull, спектральная чувствительность, зерно, цветные слои, color couplers, C-41, E-6, reversal-процесс, экспозиционная широта, сенситометрия / характеристическая кривая | C4: PL-002 / PL-006 / PL-011 / PL-012 / PL-015 / PL-016 / PL-017 / PL-018 / PL-019 / PL-020 | D4: жёлтый | E4: Химическая половина рождения фотографии: от серебряного изображения к чувствительности, зерну, цвету и экспозиционному диапазону материала.
A5: Гелиография | B5: Ньепс, битум, первое сохранившееся изображение | C5: PL-002 | D5: золотой | E5: Путь к постоянному изображению.
A6: Дагеротип | B6: прямой позитив на серебряной пластине | C6: PL-003 | D6: серебряный | E6: Резкость и публичный эффект, но уникальный экземпляр.
A7: Фотогенный рисунок / фотограмма | B7: контактные изображения объектов на бумаге | C7: PL-004 | D7: зелёный | E7: Британская линия Тальбота.
A8: Печать / тиражирование | B8: salt print, albumen print, gelatin silver print, POP/DOP, chromogenic print, фотокнига, лабораторная и сервисная печать, цветная печать с негатива, влияние зерна и экспозиции на скан/отпечаток, контактная печать, крупный негатив | C8: PL-004 / PL-013 / PL-014 / PL-015 / PL-016 / PL-019 / PL-020 / PL-028 | D8: оранжевый | E8: Ветка распространения изображений: от единичного отпечатка к массовому фотосервису, авторскому управлению финальной фактурой и контактному отпечатку крупного негатива.
A9: Печать / тиражирование | B9: salt print, albumen print, gelatin silver print, POP/DOP, chromogenic print, фотокнига, лабораторная и сервисная печать, цветная печать с негатива, влияние зерна и экспозиции на скан/отпечаток | C9: PL-004 / PL-013 / PL-014 / PL-015 / PL-016 / PL-019 / PL-020 | D9: оранжевый | E9: Ветка распространения изображений: от единичного отпечатка к массовому фотосервису и авторскому управлению финальной фактурой.
A10: Печать / тиражирование | B10: salt print, albumen print, gelatin silver print, POP/DOP, chromogenic print, фотокнига, лабораторная и сервисная печать, цветная печать с негатива | C10: PL-004 / PL-013 / PL-014 / PL-015 / PL-016 | D10: оранжевый | E10: Ветка распространения изображений: от единичного отпечатка к массовому фотосервису.
A11: Уникальный позитив | B11: ранний цвет, Autochrome, Kodachrome, Kodacolor, Ektachrome, цветная негативная и слайдовая плёнка, chromogenic print, C-41, E-6, узкая широта слайдового позитива | C11: PL-014 / PL-016 / PL-017 / PL-020 / будущие PL | D11: серый | E11: Важные, но технологически ограниченные ветки; слайдовая прозрачность особенно хорошо показывает цену ошибки экспозиции.
A12: Цвет | B12: цветные негативы, слайды, прозрачности, projected positive, Kodachrome, Ektachrome, EKTAR, EKTACOLOR, цветное зерно/красители, широта цветного негатива и слайда | C12: PL-016 / PL-017 / PL-019 / PL-020 / будущие PL | D12: радужный | E12: Цветная фотография как отдельная технологическая и визуальная линия: материал, проявка, просмотр, печать и экспозиционный допуск.
... A14: Проекция / распространение | B14: lantern slides, публичный показ | C14: будущие PL | D14: бирюзовый | E14: Мост к обучению, лекциям, презентациям.

Sheet 03_Lessons_Map
A1: Урок | B1: Главная тема | C1: Исторические узлы | D1: Что должен понять новичок | E1: Статус | F1: Ссылка на урок (Telegram)
A2: PL-001 | B2: Камера-обскура и оптика | C2: PL-HIST-0001…0008, 0013, 0028 | D2: Свет умеет строить изображение, но ещё не сохраняет его. | E2: основа готова | F2: https://t.me/photolab_vf_pro/4/40
A3: PL-002 | B3: Ньепс и первая фиксация | C3: PL-HIST-0009…0016 | D3: Недостаточно увидеть изображение — его нужно зафиксировать. | E3: основа готова | F3: https://t.me/photolab_vf_pro/4/54
A4: PL-003 | B4: Дагеротип | C4: PL-HIST-0017…0023, 0027 | D4: Фотография стала публичной, резкой и убедительной, но изображение было уникальным. | E4: основа готова | F4: https://t.me/photolab_vf_pro/4/59
A5: PL-004 | B5: Тальбот, калотип, негатив-позитив | C5: PL-HIST-0019…0026, 0029…0035 | D5: Идея копирования победила: один негатив может дать много отпечатков. | E5: основа готова | F5: https://t.me/photolab_vf_pro/4/64
A6: PL-005 | B6: Мокрый коллодий | C6: PL-HIST-0041…0048 | D6: Резкость дагеротипа и тираж калотипа встретились на стеклянной влажной пластине. | E6: основа готова | F6: https://t.me/photolab_vf_pro/4/69
A7: PL-006 | B7: Сухие желатиновые пластины | C7: PL-HIST-0049…0058 | D7: Фотография освобождается от немедленной полевой химии: пластину можно купить, хранить, экспонировать и проявлять позже. | E7: основа заполнена | F7: https://t.me/photolab_vf_pro/4/75
A8: PL-007 | B8: Рулонная плёнка и Kodak | C8: PL-HIST-0059…0068 | D8: Фотография освобождается от стеклянной пластины: рулонный носитель, Kodak и сервис обработки делают съёмку проще и ближе к массовому пользователю. | E8: основа заполнена | F8: https://t.me/photolab_vf_pro/4/105
A9: PL-008 | B9: Brownie и snapshot-культура | C9: PL-HIST-0069…0078 | D9: Фотография становится дешёвой и повседневной: обычные люди начинают снимать семью, поездки, детей и частную жизнь. | E9: основа заполнена | F9: https://t.me/photolab_vf_pro/4/110
A10: PL-009 | B10: 35 мм | C10: PL-HIST-0079…0088 | D10: 35 мм родился в кино, но стал языком компактной фотографии: киноплёнка превратилась в маленький кадр 24×36 и открыла путь Leica. | E10: основа заполнена | F10: https://t.me/photolab_vf_pro/4/118
A11: PL-010 | B11: Leica I | C11: PL-HIST-0089…0098 | D11: Leica I сделала 35 мм не просто форматом плёнки, а языком мобильной фотографии: маленькая камера стала серьёзным инструментом репортажа, улицы и повседневного наблюдения. | E11: основа заполнена | F11: https://t.me/photolab_vf_pro/4/131
A12: PL-011 | B12: Плёнка как светочувствительный материал | C12: PL-HIST-0099…0109 | D12: Плёнка — это не просто катушка, а многослойный светочувствительный материал: гибкая основа, эмульсия, серебряные соли, скрытое изображение и служебные слои. | E12: основа заполнена | F12: https://t.me/photolab_vf_pro/4/145
... A47: PL-046 | B47: Стопы света | C47: PL-HIST-0473…0483 | D47: Стопы света — общий язык экспозиции: каждый полный стоп добавляет или убирает свет в два раза через диафрагму, выдержку, ISO, фильтр или экспокоррекцию. | E47: основа заполнена | F47: https://t.me/photolab_vf_pro
A48: будущие PL | B48: Расширение после PL-046 | C48: PL-047 — недодержка; PL-048 — передержка; PL-049 — экспонометр; PL-050 — Sunny 16 | D48: После языка стопов курс переходит к ошибкам и измерению экспозиции: недодержка, передержка, экспонометр и солнечное правило. | E48: планируется

Sheet 04_Sources
A1: Источник ID | B1: Название | C1: URL | D1: Используется для | E1: Примечание
A2: SRC-001 | B2: AramcoWorld — Ibn al-Haytham: Testing is Believing | C2: https://www.aramcoworld.com/en/articles/2023/ibn-al-haytham-testing-is-believing | D2: Ибн аль-Хайсам, камера-обскура, прямолинейное распространение света | E2: вводный источник
A3: SRC-002 | B3: IMSS / Museo Galileo — Camera Obscura | C3: https://redi.imss.fi.it/inventions/index.php/Camera_Obscura | D3: Cardano, Della Porta, линза в камере-обскуре | E3: музейный образовательный источник
A4: SRC-003 | B4: Max Planck Institute — Camera Obscura PDF | C4: https://www.mpiwg-berlin.mpg.de/sites/default/files/Preprints/P307.pdf | D4: Kepler, термин camera obscura, развитие оптических приборов | E4: академический PDF
A5: SRC-004 | B5: Public Domain Review — Johann Zahn's Oculus Artificialis | C5: https://publicdomainreview.org/collection/images-from-johann-zahn-s-oculus-artificialis-1685 | D5: Johann Zahn, portable camera obscura | E5: источник по историческим изображениям
A6: SRC-005 | B6: Swiss Camera Museum — Johann Heinrich Schulze | C6: https://www.cameramuseum.ch/en/discover/permanent-exhibition/the-origins-of-photography/the-precursors-johann-heinrich-schulze/ | D6: Schulze, светочувствительность серебряных солей | E6: музейный источник
A7: SRC-006 | B7: Science History Institute — Silver and Sunlight | C7: https://www.sciencehistory.org/stories/magazine/silver-and-sunlight/ | D7: Scheele, silver chloride, ammonia | E7: научно-исторический источник
A8: SRC-007 | B8: Swiss Camera Museum — Thomas Wedgwood | C8: https://www.cameramuseum.ch/en/discover/permanent-exhibition/the-origins-of-photography/the-precursors-thomas-wedgwood/ | D8: Wedgwood, silver nitrate, early camera obscura attempts | E8: музейный источник
A9: SRC-008 | B9: Bodleian — Talbot Catalogue: Photogenic Drawing | C9: https://talbot.bodleian.ox.ac.uk/2017/02/17/an-account-of-the-processes-employed-in-photogenic-drawing/ | D9: Talbot, Wedgwood/Davy, photogenic drawing | E9: архивный/исследовательский источник
A10: SRC-009 | B10: Smithsonian NMAH — Camera Lucida | C10: https://americanhistory.si.edu/collections/object/nmah_1184286 | D10: Wollaston, Camera Lucida, 1806/1807 | E10: музейная карточка предмета
A11: SRC-010 | B11: Harry Ransom Center — The Niépce Heliograph | C11: https://www.hrc.utexas.edu/niepce-heliograph/ | D11: Niépce, View from the Window at Le Gras, heliography | E11: ключевой источник
A12: SRC-011 | B12: Maison Nicéphore Niépce — First experiments | C12: https://bicentennial-of-photography.org/niepce-and-the-invention-of-photography-niepce-s-first-experiments/ | D12: Niépce 1816, исчезающие negative images | E12: музей/юбилейный проект
... A317: SRC-315 | B317: FastRawViewer — The Unbearable Lightness of Mystic "Exposure" Triangle | C317: https://www.fastrawviewer.com/blog/mystic-exposure-triangle | D317: PL-045: critique of exposure triangle model, ISO invariance | E317: проверка технического факта, замена дубля PL-HIST-0462

Sheet 06_Lists
A1: Точность даты | B1: Статус ветки | C1: Урок | D1: Ветка | E1: Важность | F1: Уверенность | G1: Тип узла | H1: Подветка (детали)
A2: точная дата | B2: Временная доминирующая линия | C2: PL-001 | D2: Оптика / камера-обскура | E2: 1 | F2: 1 | G2: Фундаментальная предпосылка | H2: Оптика / терминология
A3: год | B3: Главная линия | C3: PL-002 | D3: Оптические инструменты | E3: 2 | F3: 2 | G3: Технология / процесс | H3: Оптика / камера
A4: примерно | B4: Главная линия / временная доминирующая линия | C4: PL-003 | D4: Фотохимия | E4: 3 | F4: 3 | G4: Инструмент / устройство | H4: Оптические инструменты / 3D
A5: диапазон | B5: Исторически важная ограниченная ветка | C5: PL-004 | D5: Гелиография | E5: 4 | F5: 4 | G5: Публикация / объявление | H5: Фотохимия / фиксация
A6: спорно/уточнить | B6: Исторически важная ограниченная ветка / художественное возрождение | C6: PL-005 | D6: Дагеротип | E6: 5 | F6: 5 | G6: Терминология / язык | H6: Фотохимия / первая фиксация
B7: Оптическая предпосылка | C7: PL-006 | D7: Фотогенный рисунок / фотограмма | G7: Связь / переход | H7: Фотохимия / публикация
B8: Переходная технология | C8: PL-007 | D8: Негатив-позитив | G8: Тиражирование / публикация | H8: Фотохимия / первая фиксация
B9: Переходная технология / художественное возрождение | C9: PL-008 | D9: Фиксаж / терминология | G9: Распространение / коммерциализация | H9: Первая фиксация / проблема постоянства
B10: Тупиковая / не получила развития | C10: PL-009 | D10: Печать / тиражирование | G10: Научное применение / пример | H10: Гелиография / первая сохранившаяся фотография
B11: Оптическая предпосылка | C11: PL-010 | D11: Мокрый коллодий | G11: Применение / жанр | H11: Передача идеи / развитие процесса
B12: Главная линия / ранний связанный дальномер | C12: PL-011 | D12: Уникальный позитив | G12: Ключевой исторический узел | H12: Дагеротип / публичное объявление
B13: Главная линия | C13: PL-012 | D13: Цвет | H13: Дагеротип / распространение
B14: Терминология / язык | C14: PL-013 | D14: Проекция / распространение | H14: Фотогенный рисунок / публикация
B15: Распространение / коммерциализация | C15: PL-014 | H15: Негатив-позитив / проявление
B16: Главная линия / пользовательское удобство | C16: PL-015 | H16: Научная фотография
B17: Применение / жанр | C17: PL-016 | H17: Цианотипия
B18: Связь / переход | C18: PL-017 | H18: Фотокнига / научная документация
B19: Главная линия / экспозиционный контроль | C19: PL-018 | H19: Фотокнига / тиражирование
B20: Главная линия / профессиональная система | C20: PL-019 | H20: Научная / медицинская фотография
B21: Главная линия / автоматизация SLR | C21: PL-020 | H21: Мокрый коллодий / распространение
B22: Главная линия / компактность | C22: PL-021 | H22: Мокрый коллодий / химия
B23: Главная линия / автофокусный компакт | C23: PL-022 | H23: Мокрый коллодий / камера
B24: Главная линия / автоматический compact | C24: PL-023 | H24: Уникальный позитив / мокрый коллодий
B25: Главная линия / премиальный компакт | C25: PL-024 | H25: Мокрый коллодий + печать
B26: Главная линия / потребительская автоматизация | C26: PL-025 | H26: Уникальный позитив / массовый портрет
... B48: Главная линия / точка съёмки | C48: будущие PL | H48: Brownie / цена и массовый рынок
B49: Главная линия / авторская ответственность | H49: Brownie / детская аудитория и реклама
B50: Главная линия / авторская работа | H50: Brownie / 120 roll film
B51: Главная линия / оптический принцип | H51: Snapshot-культура / семейный альбом
B52: Главная линия / фокусировка | H52: Snapshot-культура / любительская практика
B53: Главная линия / световой контроль | H53: Snapshot-культура / сервисная обработка
B54: Главная линия / угол зрения | H54: Brownie / долгий жизненный цикл
B55: Главная линия / тип объектива | H55: Snapshot-культура / культурный архив
B56: Главная линия / светосила | H56: Brownie / мост к 35 мм
B57: Главная линия / оптическая коррекция | H57: 35 мм / прозрачная рулонная плёнка
B58: Главная линия / просветление | H58: 35 мм / киноистоки
B59: Главная линия / оптическая схема | H59: 35 мм / ширина и перфорация
B60: Главная линия / механическая точность | H60: 35 мм / Kinetoscope
... B76: Главная линия / практическая характеристика | H76: Leica I / мост к дальномерной системе
...

Sheet 00_README
A1: PHOTO LAB — History Map Master v0.20
A2: Назначение | B2: Исследовательская база для будущей интерактивной карты развития фотографии: география + время + ветки технологий + привязка к урокам.
A3: Охват v0.17 | B3: От оптических предпосылок камеры-обскуры до Leica I, полный Модуль 2 о плёнке, Модуль 3 до PL-030, Модуль 4 до PL-039; Модуль 5 заполнен PL-041–PL-046. PL-040 пока оставлен отдельным будущим заполнением.
A4: Принцип | B4: Каждый факт должен отвечать на 5 вопросов: что произошло, где, кто связан, почему важно, чем подтверждено.
A5: Как пользоваться | B5: Фильтровать лист 01_Master_Facts по уроку, ветке развития, статусу ветки, типу узла, стране или уровню уверенности.
A6: Важно | B6: Поля «Проверить позже» и «Уверенность 1–5» оставлены специально: спорные даты и слабые источники не должны попадать в финальную карту без доработки.
A7: Правило веток | B7: Колонка H «Ветка развития» должна содержать только крупные ветки из листа 02_Branches. PL-024–PL-028 остаются внутри ветки «Оптические инструменты», кроме отдельных узлов печати/фотохимии для большого формата.
A8: Правило подветок | B8: Детализация хранится в колонке Y «Подветка (детали)»: дальномер, SLR, compact, средний формат, большой формат, view camera, подвижки и т.д. Это позволяет карте фильтровать крупно и подробно одновременно.
A9: Правило типа узла | B9: Тип узла = назначение факта на карте: технология, предпосылка, инструмент, публикация, терминология, применение, распространение, связь/переход и т.п.
A10: Единственный источник истины по урокам | B10: Для фильтра «по уроку» использовать только колонку «Привязка к уроку» в 01_Master_Facts. Диапазоны в 03_Lessons_Map — нарративные, не строгие множества, и могут пересекаться между уроками.
A11: Что изменено в v0.2.1 | B11: Исправлены формулы Dashboard с безопасными ссылками на листы, убрана остаточная строка «Цианотипия», нормализованы выпадающие списки, добавлена колонка «Тип узла», подготовлена строка PL-006.
A12: Что изменено в v0.3 | B12: Заполнен PL-006: добавлены PL-HIST-0049…0058 по сухим желатиновым пластинам, добавлены источники SRC-027…SRC-034, обновлены 02_Branches, 03_Lessons_Map, 06_Lists и Dashboard.
A13: Что изменено в v0.3.1 | B13: Добавлена колонка «Флагман урока (да/нет)» в 01_Master_Facts: по одному флагманскому узлу на каждый из PL-001–PL-006.
... A36: Следующий шаг | B36: PL-047: Недодержка — разобрать нехватку света, потерю деталей в тенях, отличие плёнки и цифры, экспокоррекцию и практику намеренной/случайной недодержки. PL-040 остаётся отдельным долгом в Модуле 4.
